Workbook

Sheet Daily
A1: Student | B1: Service Date | C1: Session Time | D1: Session Duration | E1: Hours | F1: Pay | G1: Units | H1: FNF | I1: Code | J1: Charged Amount | K1: User | L1: Level | M1: Note | N1: Unbilled notes | O1: Expiration Date
A2: Abdi, Ahmed | B2: 46014 | C2: 03:30pm - 08:00pm | E2: =HOUR(D2)+MINUTE(D2)/100 | F2: =ROUND(INT(E2) + (E2 - INT(E2)) * 100 / 60, 2) | G2: =E2*4 | H2: =LET(total, INT(E2)*60 + (E2-INT(E2))*100, blocks, QUOTIENT(total, 15), extra, MOD(total, 15), units, blocks + IF(extra>=8, 1, 0), units) | I2: 1/1 97153 | J2: =IF(L2="Level 1", VLOOKUP(I2, UserCodes!E:F, 2, FALSE) * H2, IF(L2="Level 2", VLOOKUP(I2, UserCodes!E:F, 2, FALSE) * H2 * 0.8, 0)) | K2: Ibrahim, Ahmed | L2: =VLOOKUP(K2, UserCodes!A:B, 2, FALSE) | M2: No note
A3: Abdi, Ahmed | B3: 46013 | C3: 04:00pm - 07:00pm | E3: =HOUR(D3)+MINUTE(D3)/100 | F3: =ROUND(INT(E3) + (E3 - INT(E3)) * 100 / 60, 2) | G3: =E3*4 | H3: =LET(total, INT(E3)*60 + (E3-INT(E3))*100, blocks, QUOTIENT(total, 15), extra, MOD(total, 15), units, blocks + IF(extra>=8, 1, 0), units) | I3: O&D 97155 | J3: =IF(L3="Level 1", VLOOKUP(I3, UserCodes!E:F, 2, FALSE) * H3, IF(L3="Level 2", VLOOKUP(I3, UserCodes!E:F, 2, FALSE) * H3 * 0.8, 0)) | K3: Ibrahim, Ahmed | L3: =VLOOKUP(K3, UserCodes!A:B, 2, FALSE) | M3: No note
A4: Abdi, Ahmed | B4: 46003 | C4: 05:00pm - 06:00pm | E4: =HOUR(D4)+MINUTE(D4)/100 | F4: =ROUND(INT(E4) + (E4 - INT(E4)) * 100 / 60, 2) | G4: =E4*4 | H4: =LET(total, INT(E4)*60 + (E4-INT(E4))*100, blocks, QUOTIENT(total, 15), extra, MOD(total, 15), units, blocks + IF(extra>=8, 1, 0), units) | I4: 1/1 97153 | J4: =IF(L4="Level 1", VLOOKUP(I4, UserCodes!E:F, 2, FALSE) * H4, IF(L4="Level 2", VLOOKUP(I4, UserCodes!E:F, 2, FALSE) * H4 * 0.8, 0)) | K4: Abdulle, Zamzam | L4: =VLOOKUP(K4, UserCodes!A:B, 2, FALSE) | M4: No note
A5: Abdi, Mohamed | B5: 46013 | C5: 03:00pm - 08:00pm | E5: =HOUR(D5)+MINUTE(D5)/100 | F5: =ROUND(INT(E5) + (E5 - INT(E5)) * 100 / 60, 2) | G5: =E5*4 | H5: =LET(total, INT(E5)*60 + (E5-INT(E5))*100, blocks, QUOTIENT(total, 15), extra, MOD(total, 15), units, blocks + IF(extra>=8, 1, 0), units) | I5: 1/1 97153 | J5: =IF(L5="Level 1", VLOOKUP(I5, UserCodes!E:F, 2, FALSE) * H5, IF(L5="Level 2", VLOOKUP(I5, UserCodes!E:F, 2, FALSE) * H5 * 0.8, 0)) | K5: Mohamed, Mohamed | L5: =VLOOKUP(K5, UserCodes!A:B, 2, FALSE) | M5: No note
A6: Abdi, Mohamed | B6: 46013 | C6: 07:00pm - 08:00pm | E6: =HOUR(D6)+MINUTE(D6)/100 | F6: =ROUND(INT(E6) + (E6 - INT(E6)) * 100 / 60, 2) | G6: =E6*4 | H6: =LET(total, INT(E6)*60 + (E6-INT(E6))*100, blocks, QUOTIENT(total, 15), extra, MOD(total, 15), units, blocks + IF(extra>=8, 1, 0), units) | I6: O&D 97155 | J6: =IF(L6="Level 1", VLOOKUP(I6, UserCodes!E:F, 2, FALSE) * H6, IF(L6="Level 2", VLOOKUP(I6, UserCodes!E:F, 2, FALSE) * H6 * 0.8, 0)) | K6: Ibrahim, Ahmed | L6: =VLOOKUP(K6, UserCodes!A:B, 2, FALSE) | M6: No note
A7: Abdi, Safia | B7: 46014 | C7: 04:30pm - 06:30pm | E7: =HOUR(D7)+MINUTE(D7)/100 | F7: =ROUND(INT(E7) + (E7 - INT(E7)) * 100 / 60, 2) | G7: =E7*4 | H7: =LET(total, INT(E7)*60 + (E7-INT(E7))*100, blocks, QUOTIENT(total, 15), extra, MOD(total, 15), units, blocks + IF(extra>=8, 1, 0), units) | I7: O&D 97155 | J7: =IF(L7="Level 1", VLOOKUP(I7, UserCodes!E:F, 2, FALSE) * H7, IF(L7="Level 2", VLOOKUP(I7, UserCodes!E:F, 2, FALSE) * H7 * 0.8, 0)) | K7: mohamed, Madar | L7: =VLOOKUP(K7, UserCodes!A:B, 2, FALSE) | M7: No note
A8: Abdi, Safia | B8: 46012 | C8: 01:30 AM - 03:45 PM | D8: 14:15 | E8: =HOUR(D8)+MINUTE(D8)/100 | F8: =ROUND(INT(E8) + (E8 - INT(E8)) * 100 / 60, 2) | G8: =E8*4 | H8: =LET(total, INT(E8)*60 + (E8-INT(E8))*100, blocks, QUOTIENT(total, 15), extra, MOD(total, 15), units, blocks + IF(extra>=8, 1, 0), units) | J8: =IF(L8="Level 1", VLOOKUP(I8, UserCodes!E:F, 2, FALSE) * H8, IF(L8="Level 2", VLOOKUP(I8, UserCodes!E:F, 2, FALSE) * H8 * 0.8, 0)) | K8: Ahmed, Jama | L8: =VLOOKUP(K8, UserCodes!A:B, 2, FALSE) | M8: No schedule
A9: Abdi, Safia | B9: 46013 | C9: 02:00pm - 04:00pm | E9: =HOUR(D9)+MINUTE(D9)/100 | F9: =ROUND(INT(E9) + (E9 - INT(E9)) * 100 / 60, 2) | G9: =E9*4 | H9: =LET(total, INT(E9)*60 + (E9-INT(E9))*100, blocks, QUOTIENT(total, 15), extra, MOD(total, 15), units, blocks + IF(extra>=8, 1, 0), units) | I9: O&D 97155 | J9: =IF(L9="Level 1", VLOOKUP(I9, UserCodes!E:F, 2, FALSE) * H9, IF(L9="Level 2", VLOOKUP(I9, UserCodes!E:F, 2, FALSE) * H9 * 0.8, 0)) | K9: Ibrahim, Ahmed | L9: =VLOOKUP(K9, UserCodes!A:B, 2, FALSE) | M9: No note
A10: Abdi, Safia | B10: 46013 | C10: 02:00pm - 08:00pm | E10: =HOUR(D10)+MINUTE(D10)/100 | F10: =ROUND(INT(E10) + (E10 - INT(E10)) * 100 / 60, 2) | G10: =E10*4 | H10: =LET(total, INT(E10)*60 + (E10-INT(E10))*100, blocks, QUOTIENT(total, 15), extra, MOD(total, 15), units, blocks + IF(extra>=8, 1, 0), units) | I10: 1/1 97153 | J10: =IF(L10="Level 1", VLOOKUP(I10, UserCodes!E:F, 2, FALSE) * H10, IF(L10="Level 2", VLOOKUP(I10, UserCodes!E:F, 2, FALSE) * H10 * 0.8, 0)) | K10: Muse, Nawaal | L10: =VLOOKUP(K10, UserCodes!A:B, 2, FALSE) | M10: No note
A11: Abdi, Safia | B11: 46008 | C11: 09:45 AM - 11:30 AM | D11: 01:45 | E11: =HOUR(D11)+MINUTE(D11)/100 | F11: =ROUND(INT(E11) + (E11 - INT(E11)) * 100 / 60, 2) | G11: =E11*4 | H11: =LET(total, INT(E11)*60 + (E11-INT(E11))*100, blocks, QUOTIENT(total, 15), extra, MOD(total, 15), units, blocks + IF(extra>=8, 1, 0), units) | J11: =IF(L11="Level 1", VLOOKUP(I11, UserCodes!E:F, 2, FALSE) * H11, IF(L11="Level 2", VLOOKUP(I11, UserCodes!E:F, 2, FALSE) * H11 * 0.8, 0)) | K11: Ahmed, Jama | L11: =VLOOKUP(K11, UserCodes!A:B, 2, FALSE) | M11: No schedule
A12: Abdi, Safia | B12: 46004 | C12: 09:00 AM - 11:30 AM | D12: 02:30 | E12: =HOUR(D12)+MINUTE(D12)/100 | F12: =ROUND(INT(E12) + (E12 - INT(E12)) * 100 / 60, 2) | G12: =E12*4 | H12: =LET(total, INT(E12)*60 + (E12-INT(E12))*100, blocks, QUOTIENT(total, 15), extra, MOD(total, 15), units, blocks + IF(extra>=8, 1, 0), units) | J12: =IF(L12="Level 1", VLOOKUP(I12, UserCodes!E:F, 2, FALSE) * H12, IF(L12="Level 2", VLOOKUP(I12, UserCodes!E:F, 2, FALSE) * H12 * 0.8, 0)) | K12: Ahmed, Jama | L12: =VLOOKUP(K12, UserCodes!A:B, 2, FALSE) | M12: No schedule
A13: Abdi, Safia | B13: 46002 | C13: 01:28 PM - 03:50 PM | D13: 02:22 | E13: =HOUR(D13)+MINUTE(D13)/100 | F13: =ROUND(INT(E13) + (E13 - INT(E13)) * 100 / 60, 2) | G13: =E13*4 | H13: =LET(total, INT(E13)*60 + (E13-INT(E13))*100, blocks, QUOTIENT(total, 15), extra, MOD(total, 15), units, blocks + IF(extra>=8, 1, 0), units) | J13: =IF(L13="Level 1", VLOOKUP(I13, UserCodes!E:F, 2, FALSE) * H13, IF(L13="Level 2", VLOOKUP(I13, UserCodes!E:F, 2, FALSE) * H13 * 0.8, 0)) | K13: Ahmed, Jama | L13: =VLOOKUP(K13, UserCodes!A:B, 2, FALSE) | M13: No schedule
A14: Abdi, Safia | B14: 46003 | C14: 04:00 PM - 05:00 PM | D14: 01:00 | E14: =HOUR(D14)+MINUTE(D14)/100 | F14: =ROUND(INT(E14) + (E14 - INT(E14)) * 100 / 60, 2) | G14: =E14*4 | H14: =LET(total, INT(E14)*60 + (E14-INT(E14))*100, blocks, QUOTIENT(total, 15), extra, MOD(total, 15), units, blocks + IF(extra>=8, 1, 0), units) | J14: =IF(L14="Level 1", VLOOKUP(I14, UserCodes!E:F, 2, FALSE) * H14, IF(L14="Level 2", VLOOKUP(I14, UserCodes!E:F, 2, FALSE) * H14 * 0.8, 0)) | K14: El-Tay, Dr. Ismael | L14: =VLOOKUP(K14, UserCodes!A:B, 2, FALSE) | M14: No schedule
A15: Abdi, Salman | B15: 46014 | C15: 12:00pm - 04:00pm | E15: =HOUR(D15)+MINUTE(D15)/100 | F15: =ROUND(INT(E15) + (E15 - INT(E15)) * 100 / 60, 2) | G15: =E15*4 | H15: =LET(total, INT(E15)*60 + (E15-INT(E15))*100, blocks, QUOTIENT(total, 15), extra, MOD(total, 15), units, blocks + IF(extra>=8, 1, 0), units) | I15: 1/1 97153 | J15: =IF(L15="Level 1", VLOOKUP(I15, UserCodes!E:F, 2, FALSE) * H15, IF(L15="Level 2", VLOOKUP(I15, UserCodes!E:F, 2, FALSE) * H15 * 0.8, 0)) | K15: Abdulle, Zamzam | L15: =VLOOKUP(K15, UserCodes!A:B, 2, FALSE) | M15: No note
A16: Abdi, Salman | B16: 46014 | C16: 04:30 PM - 06:30 PM | D16: 02:00 | E16: =HOUR(D16)+MINUTE(D16)/100 | F16: =ROUND(INT(E16) + (E16 - INT(E16)) * 100 / 60, 2) | G16: =E16*4 | H16: =LET(total, INT(E16)*60 + (E16-INT(E16))*100, blocks, QUOTIENT(total, 15), extra, MOD(total, 15), units, blocks + IF(extra>=8, 1, 0), units) | J16: =IF(L16="Level 1", VLOOKUP(I16, UserCodes!E:F, 2, FALSE) * H16, IF(L16="Level 2", VLOOKUP(I16, UserCodes!E:F, 2, FALSE) * H16 * 0.8, 0)) | K16: Mohamed, Madar | L16: =VLOOKUP(K16, UserCodes!A:B, 2, FALSE) | M16: No schedule
A17: Abdi, Salman | B17: 46014 | C17: 09:00 AM - 11:45 AM | D17: 02:45 | E17: =HOUR(D17)+MINUTE(D17)/100 | F17: =ROUND(INT(E17) + (E17 - INT(E17)) * 100 / 60, 2) | G17: =E17*4 | H17: =LET(total, INT(E17)*60 + (E17-INT(E17))*100, blocks, QUOTIENT(total, 15), extra, MOD(total, 15), units, blocks + IF(extra>=8, 1, 0), units) | J17: =IF(L17="Level 1", VLOOKUP(I17, UserCodes!E:F, 2, FALSE) * H17, IF(L17="Level 2", VLOOKUP(I17, UserCodes!E:F, 2, FALSE) * H17 * 0.8, 0)) | K17: Ahmed, Jama | L17: =VLOOKUP(K17, UserCodes!A:B, 2, FALSE) | M17: No schedule
A18: Abdi, Samira | B18: 46003 | C18: 04:00pm - 08:00pm | E18: =HOUR(D18)+MINUTE(D18)/100 | F18: =ROUND(INT(E18) + (E18 - INT(E18)) * 100 / 60, 2) | G18: =E18*4 | H18: =LET(total, INT(E18)*60 + (E18-INT(E18))*100, blocks, QUOTIENT(total, 15), extra, MOD(total, 15), units, blocks + IF(extra>=8, 1, 0), units) | I18: 1/1 97153 | J18: =IF(L18="Level 1", VLOOKUP(I18, UserCodes!E:F, 2, FALSE) * H18, IF(L18="Level 2", VLOOKUP(I18, UserCodes!E:F, 2, FALSE) * H18 * 0.8, 0)) | K18: Abdulle, Zamzam | L18: =VLOOKUP(K18, UserCodes!A:B, 2, FALSE) | M18: No note
A19: Abdi, Samira | B19: 46003 | C19: 09:00 AM - 11:30 AM | D19: 02:30 | E19: =HOUR(D19)+MINUTE(D19)/100 | F19: =ROUND(INT(E19) + (E19 - INT(E19)) * 100 / 60, 2) | G19: =E19*4 | H19: =LET(total, INT(E19)*60 + (E19-INT(E19))*100, blocks, QUOTIENT(total, 15), extra, MOD(total, 15), units, blocks + IF(extra>=8, 1, 0), units) | J19: =IF(L19="Level 1", VLOOKUP(I19, UserCodes!E:F, 2, FALSE) * H19, IF(L19="Level 2", VLOOKUP(I19, UserCodes!E:F, 2, FALSE) * H19 * 0.8, 0)) | K19: Ahmed, Jama | L19: =VLOOKUP(K19, UserCodes!A:B, 2, FALSE) | M19: No schedule
A20: Abdi, Samira | B20: 46002 | C20: 05:00 PM - 06:00 PM | D20: 01:00 | E20: =HOUR(D20)+MINUTE(D20)/100 | F20: =ROUND(INT(E20) + (E20 - INT(E20)) * 100 / 60, 2) | G20: =E20*4 | H20: =LET(total, INT(E20)*60 + (E20-INT(E20))*100, blocks, QUOTIENT(total, 15), extra, MOD(total, 15), units, blocks + IF(extra>=8, 1, 0), units) | J20: =IF(L20="Level 1", VLOOKUP(I20, UserCodes!E:F, 2, FALSE) * H20, IF(L20="Level 2", VLOOKUP(I20, UserCodes!E:F, 2, FALSE) * H20 * 0.8, 0)) | K20: El-Tay, Dr. Ismael | L20: =VLOOKUP(K20, UserCodes!A:B, 2, FALSE) | M20: No schedule
A21: Abdi, Samira | B21: 46013 | C21: 09:30 AM - 11:45 AM | D21: 02:15 | E21: =HOUR(D21)+MINUTE(D21)/100 | F21: =ROUND(INT(E21) + (E21 - INT(E21)) * 100 / 60, 2) | G21: =E21*4 | H21: =LET(total, INT(E21)*60 + (E21-INT(E21))*100, blocks, QUOTIENT(total, 15), extra, MOD(total, 15), units, blocks + IF(extra>=8, 1, 0), units) | J21: =IF(L21="Level 1", VLOOKUP(I21, UserCodes!E:F, 2, FALSE) * H21, IF(L21="Level 2", VLOOKUP(I21, UserCodes!E:F, 2, FALSE) * H21 * 0.8, 0)) | K21: Ahmed, Jama | L21: =VLOOKUP(K21, UserCodes!A:B, 2, FALSE) | M21: No schedule
A22: Abdi, Samira | B22: 46001 | C22: 10:00 AM - 12:30 PM | D22: 02:30 | E22: =HOUR(D22)+MINUTE(D22)/100 | F22: =ROUND(INT(E22) + (E22 - INT(E22)) * 100 / 60, 2) | G22: =E22*4 | H22: =LET(total, INT(E22)*60 + (E22-INT(E22))*100, blocks, QUOTIENT(total, 15), extra, MOD(total, 15), units, blocks + IF(extra>=8, 1, 0), units) | J22: =IF(L22="Level 1", VLOOKUP(I22, UserCodes!E:F, 2, FALSE) * H22, IF(L22="Level 2", VLOOKUP(I22, UserCodes!E:F, 2, FALSE) * H22 * 0.8, 0)) | K22: Ahmed, Jama | L22: =VLOOKUP(K22, UserCodes!A:B, 2, FALSE) | M22: No schedule
A23: Abdi, Samira | B23: 46009 | C23: 12:55 PM - 03:10 PM | D23: 02:15 | E23: =HOUR(D23)+MINUTE(D23)/100 | F23: =ROUND(INT(E23) + (E23 - INT(E23)) * 100 / 60, 2) | G23: =E23*4 | H23: =LET(total, INT(E23)*60 + (E23-INT(E23))*100, blocks, QUOTIENT(total, 15), extra, MOD(total, 15), units, blocks + IF(extra>=8, 1, 0), units) | J23: =IF(L23="Level 1", VLOOKUP(I23, UserCodes!E:F, 2, FALSE) * H23, IF(L23="Level 2", VLOOKUP(I23, UserCodes!E:F, 2, FALSE) * H23 * 0.8, 0)) | K23: Ahmed, Jama | L23: =VLOOKUP(K23, UserCodes!A:B, 2, FALSE) | M23: No schedule
A24: Abdi, Samira | B24: 46009 | C24: 04:00pm - 05:00pm | E24: =HOUR(D24)+MINUTE(D24)/100 | F24: =ROUND(INT(E24) + (E24 - INT(E24)) * 100 / 60, 2) | G24: =E24*4 | H24: =LET(total, INT(E24)*60 + (E24-INT(E24))*100, blocks, QUOTIENT(total, 15), extra, MOD(total, 15), units, blocks + IF(extra>=8, 1, 0), units) | I24: 1/1 97153 | J24: =IF(L24="Level 1", VLOOKUP(I24, UserCodes!E:F, 2, FALSE) * H24, IF(L24="Level 2", VLOOKUP(I24, UserCodes!E:F, 2, FALSE) * H24 * 0.8, 0)) | K24: Abdulle, Zamzam | L24: =VLOOKUP(K24, UserCodes!A:B, 2, FALSE) | M24: No note
A25: Abdi, Samira | B25: 46007 | C25: 01:35 PM - 03:55 PM | D25: 02:20 | E25: =HOUR(D25)+MINUTE(D25)/100 | F25: =ROUND(INT(E25) + (E25 - INT(E25)) * 100 / 60, 2) | G25: =E25*4 | H25: =LET(total, INT(E25)*60 + (E25-INT(E25))*100, blocks, QUOTIENT(total, 15), extra, MOD(total, 15), units, blocks + IF(extra>=8, 1, 0), units) | J25: =IF(L25="Level 1", VLOOKUP(I25, UserCodes!E:F, 2, FALSE) * H25, IF(L25="Level 2", VLOOKUP(I25, UserCodes!E:F, 2, FALSE) * H25 * 0.8, 0)) | K25: Ahmed, Jama | L25: =VLOOKUP(K25, UserCodes!A:B, 2, FALSE) | M25: No schedule
A26: Abdulkadir, Nadra | B26: 46013 | C26: 01:00 PM - 03:15 PM | D26: 02:15 | E26: =HOUR(D26)+MINUTE(D26)/100 | F26: =ROUND(INT(E26) + (E26 - INT(E26)) * 100 / 60, 2) | G26: =E26*4 | H26: =LET(total, INT(E26)*60 + (E26-INT(E26))*100, blocks, QUOTIENT(total, 15), extra, MOD(total, 15), units, blocks + IF(extra>=8, 1, 0), units) | J26: =IF(L26="Level 1", VLOOKUP(I26, UserCodes!E:F, 2, FALSE) * H26, IF(L26="Level 2", VLOOKUP(I26, UserCodes!E:F, 2, FALSE) * H26 * 0.8, 0)) | K26: Ahmed, Jama | L26: =VLOOKUP(K26, UserCodes!A:B, 2, FALSE) | M26: No schedule
A27: Abdulkadir, Nadra | B27: 46001 | C27: 01:30 PM - 03:50 PM | D27: 02:20 | E27: =HOUR(D27)+MINUTE(D27)/100 | F27: =ROUND(INT(E27) + (E27 - INT(E27)) * 100 / 60, 2) | G27: =E27*4 | H27: =LET(total, INT(E27)*60 + (E27-INT(E27))*100, blocks, QUOTIENT(total, 15), extra, MOD(total, 15), units, blocks + IF(extra>=8, 1, 0), units) | J27: =IF(L27="Level 1", VLOOKUP(I27, UserCodes!E:F, 2, FALSE) * H27, IF(L27="Level 2", VLOOKUP(I27, UserCodes!E:F, 2, FALSE) * H27 * 0.8, 0)) | K27: Ahmed, Jama | L27: =VLOOKUP(K27, UserCodes!A:B, 2, FALSE) | M27: No schedule
A28: Abdulkadir, Nadra | B28: 46002 | C28: 11:30am - 02:30pm | E28: =HOUR(D28)+MINUTE(D28)/100 | F28: =ROUND(INT(E28) + (E28 - INT(E28)) * 100 / 60, 2) | G28: =E28*4 | H28: =LET(total, INT(E28)*60 + (E28-INT(E28))*100, blocks, QUOTIENT(total, 15), extra, MOD(total, 15), units, blocks + IF(extra>=8, 1, 0), units) | I28: O&D 97155 | J28: =IF(L28="Level 1", VLOOKUP(I28, UserCodes!E:F, 2, FALSE) * H28, IF(L28="Level 2", VLOOKUP(I28, UserCodes!E:F, 2, FALSE) * H28 * 0.8, 0)) | K28: mohamed, Madar | L28: =VLOOKUP(K28, UserCodes!A:B, 2, FALSE) | M28: No note
A29: Abdulkadir, Nadra | B29: 46005 | C29: 09:30 AM - 11:45 AM | D29: 02:15 | E29: =HOUR(D29)+MINUTE(D29)/100 | F29: =ROUND(INT(E29) + (E29 - INT(E29)) * 100 / 60, 2) | G29: =E29*4 | H29: =LET(total, INT(E29)*60 + (E29-INT(E29))*100, blocks, QUOTIENT(total, 15), extra, MOD(total, 15), units, blocks + IF(extra>=8, 1, 0), units) | J29: =IF(L29="Level 1", VLOOKUP(I29, UserCodes!E:F, 2, FALSE) * H29, IF(L29="Level 2", VLOOKUP(I29, UserCodes!E:F, 2, FALSE) * H29 * 0.8, 0)) | K29: Ahmed, Jama | L29: =VLOOKUP(K29, UserCodes!A:B, 2, FALSE) | M29: No schedule
A30: Abdullahi, Abdirahman | B30: 46005 | C30: 12:50 PM - 03:30 PM | D30: 02:40 | E30: =HOUR(D30)+MINUTE(D30)/100 | F30: =ROUND(INT(E30) + (E30 - INT(E30)) * 100 / 60, 2) | G30: =E30*4 | H30: =LET(total, INT(E30)*60 + (E30-INT(E30))*100, blocks, QUOTIENT(total, 15), extra, MOD(total, 15), units, blocks + IF(extra>=8, 1, 0), units) | J30: =IF(L30="Level 1", VLOOKUP(I30, UserCodes!E:F, 2, FALSE) * H30, IF(L30="Level 2", VLOOKUP(I30, UserCodes!E:F, 2, FALSE) * H30 * 0.8, 0)) | K30: Ahmed, Jama | L30: =VLOOKUP(K30, UserCodes!A:B, 2, FALSE) | M30: No schedule
A31: Abdullahi, Abdirahman | B31: 46008 | C31: 01:00pm - 04:00pm | E31: =HOUR(D31)+MINUTE(D31)/100 | F31: =ROUND(INT(E31) + (E31 - INT(E31)) * 100 / 60, 2) | G31: =E31*4 | H31: =LET(total, INT(E31)*60 + (E31-INT(E31))*100, blocks, QUOTIENT(total, 15), extra, MOD(total, 15), units, blocks + IF(extra>=8, 1, 0), units) | I31: 1/1 97153 | J31: =IF(L31="Level 1", VLOOKUP(I31, UserCodes!E:F, 2, FALSE) * H31, IF(L31="Level 2", VLOOKUP(I31, UserCodes!E:F, 2, FALSE) * H31 * 0.8, 0)) | K31: Ali, Nasteho | L31: =VLOOKUP(K31, UserCodes!A:B, 2, FALSE) | M31: No note
A32: Abdullahi, Abdirahman | B32: 46002 | C32: 09:30 AM - 11:45 AM | D32: 02:15 | E32: =HOUR(D32)+MINUTE(D32)/100 | F32: =ROUND(INT(E32) + (E32 - INT(E32)) * 100 / 60, 2) | G32: =E32*4 | H32: =LET(total, INT(E32)*60 + (E32-INT(E32))*100, blocks, QUOTIENT(total, 15), extra, MOD(total, 15), units, blocks + IF(extra>=8, 1, 0), units) | J32: =IF(L32="Level 1", VLOOKUP(I32, UserCodes!E:F, 2, FALSE) * H32, IF(L32="Level 2", VLOOKUP(I32, UserCodes!E:F, 2, FALSE) * H32 * 0.8, 0)) | K32: Ahmed, Jama | L32: =VLOOKUP(K32, UserCodes!A:B, 2, FALSE) | M32: No schedule
A33: Abdullahi, Abdirahman | B33: 46008 | C33: 12:45 PM - 02:50 PM | D33: 02:05 | E33: =HOUR(D33)+MINUTE(D33)/100 | F33: =ROUND(INT(E33) + (E33 - INT(E33)) * 100 / 60, 2) | G33: =E33*4 | H33: =LET(total, INT(E33)*60 + (E33-INT(E33))*100, blocks, QUOTIENT(total, 15), extra, MOD(total, 15), units, blocks + IF(extra>=8, 1, 0), units) | J33: =IF(L33="Level 1", VLOOKUP(I33, UserCodes!E:F, 2, FALSE) * H33, IF(L33="Level 2", VLOOKUP(I33, UserCodes!E:F, 2, FALSE) * H33 * 0.8, 0)) | K33: Ahmed, Jama | L33: =VLOOKUP(K33, UserCodes!A:B, 2, FALSE) | M33: No schedule
A34: Abdullahi, Abdirahman | B34: 46014 | C34: 01:30pm - 03:00pm | E34: =HOUR(D34)+MINUTE(D34)/100 | F34: =ROUND(INT(E34) + (E34 - INT(E34)) * 100 / 60, 2) | G34: =E34*4 | H34: =LET(total, INT(E34)*60 + (E34-INT(E34))*100, blocks, QUOTIENT(total, 15), extra, MOD(total, 15), units, blocks + IF(extra>=8, 1, 0), units) | I34: 1/1 97153 | J34: =IF(L34="Level 1", VLOOKUP(I34, UserCodes!E:F, 2, FALSE) * H34, IF(L34="Level 2", VLOOKUP(I34, UserCodes!E:F, 2, FALSE) * H34 * 0.8, 0)) | K34: Ibrahim, Ahmed | L34: =VLOOKUP(K34, UserCodes!A:B, 2, FALSE) | M34: No note
A35: Abdullahi, Abdirahman | B35: 46006 | C35: 01:00pm - 04:00pm | E35: =HOUR(D35)+MINUTE(D35)/100 | F35: =ROUND(INT(E35) + (E35 - INT(E35)) * 100 / 60, 2) | G35: =E35*4 | H35: =LET(total, INT(E35)*60 + (E35-INT(E35))*100, blocks, QUOTIENT(total, 15), extra, MOD(total, 15), units, blocks + IF(extra>=8, 1, 0), units) | I35: O&D 97155 | J35: =IF(L35="Level 1", VLOOKUP(I35, UserCodes!E:F, 2, FALSE) * H35, IF(L35="Level 2", VLOOKUP(I35, UserCodes!E:F, 2, FALSE) * H35 * 0.8, 0)) | K35: Abdulle, Zamzam | L35: =VLOOKUP(K35, UserCodes!A:B, 2, FALSE) | M35: No note
A36: Abdullahi, Abdirahman | B36: 46014 | C36: 01:00pm - 01:30pm | E36: =HOUR(D36)+MINUTE(D36)/100 | F36: =ROUND(INT(E36) + (E36 - INT(E36)) * 100 / 60, 2) | G36: =E36*4 | H36: =LET(total, INT(E36)*60 + (E36-INT(E36))*100, blocks, QUOTIENT(total, 15), extra, MOD(total, 15), units, blocks + IF(extra>=8, 1, 0), units) | I36: 1/1 97153 | J36: =IF(L36="Level 1", VLOOKUP(I36, UserCodes!E:F, 2, FALSE) * H36, IF(L36="Level 2", VLOOKUP(I36, UserCodes!E:F, 2, FALSE) * H36 * 0.8, 0)) | K36: Ibrahim, Ahmed | L36: =VLOOKUP(K36, UserCodes!A:B, 2, FALSE) | M36: No note
A37: Ali, Saami | B37: 46011 | C37: 04:00pm - 06:00pm | E37: =HOUR(D37)+MINUTE(D37)/100 | F37: =ROUND(INT(E37) + (E37 - INT(E37)) * 100 / 60, 2) | G37: =E37*4 | H37: =LET(total, INT(E37)*60 + (E37-INT(E37))*100, blocks, QUOTIENT(total, 15), extra, MOD(total, 15), units, blocks + IF(extra>=8, 1, 0), units) | I37: O&D 97155 | J37: =IF(L37="Level 1", VLOOKUP(I37, UserCodes!E:F, 2, FALSE) * H37, IF(L37="Level 2", VLOOKUP(I37, UserCodes!E:F, 2, FALSE) * H37 * 0.8, 0)) | K37: Ibrahim, Ahmed | L37: =VLOOKUP(K37, UserCodes!A:B, 2, FALSE) | M37: No note
A38: Jama, Khadija | B38: 46010 | C38: 09:25 AM - 11:40 AM | D38: 02:15 | E38: =HOUR(D38)+MINUTE(D38)/100 | F38: =ROUND(INT(E38) + (E38 - INT(E38)) * 100 / 60, 2) | G38: =E38*4 | H38: =LET(total, INT(E38)*60 + (E38-INT(E38))*100, blocks, QUOTIENT(total, 15), extra, MOD(total, 15), units, blocks + IF(extra>=8, 1, 0), units) | J38: =IF(L38="Level 1", VLOOKUP(I38, UserCodes!E:F, 2, FALSE) * H38, IF(L38="Level 2", VLOOKUP(I38, UserCodes!E:F, 2, FALSE) * H38 * 0.8, 0)) | K38: Ahmed, Jama | L38: =VLOOKUP(K38, UserCodes!A:B, 2, FALSE) | M38: No schedule
A39: Jama, Khadija | B39: 46004 | C39: 10:00am - 03:00pm | E39: =HOUR(D39)+MINUTE(D39)/100 | F39: =ROUND(INT(E39) + (E39 - INT(E39)) * 100 / 60, 2) | G39: =E39*4 | H39: =LET(total, INT(E39)*60 + (E39-INT(E39))*100, blocks, QUOTIENT(total, 15), extra, MOD(total, 15), units, blocks + IF(extra>=8, 1, 0), units) | I39: 1/1 97153 | J39: =IF(L39="Level 1", VLOOKUP(I39, UserCodes!E:F, 2, FALSE) * H39, IF(L39="Level 2", VLOOKUP(I39, UserCodes!E:F, 2, FALSE) * H39 * 0.8, 0)) | K39: Abdulle, Zamzam | L39: =VLOOKUP(K39, UserCodes!A:B, 2, FALSE) | M39: No note
A40: Kadir, Hamdi | B40: 46003 | C40: 12:55 PM - 03:45 PM | D40: 02:50 | E40: =HOUR(D40)+MINUTE(D40)/100 | F40: =ROUND(INT(E40) + (E40 - INT(E40)) * 100 / 60, 2) | G40: =E40*4 | H40: =LET(total, INT(E40)*60 + (E40-INT(E40))*100, blocks, QUOTIENT(total, 15), extra, MOD(total, 15), units, blocks + IF(extra>=8, 1, 0), units) | J40: =IF(L40="Level 1", VLOOKUP(I40, UserCodes!E:F, 2, FALSE) * H40, IF(L40="Level 2", VLOOKUP(I40, UserCodes!E:F, 2, FALSE) * H40 * 0.8, 0)) | K40: Ahmed, Jama | L40: =VLOOKUP(K40, UserCodes!A:B, 2, FALSE) | M40: No schedule
...

Sheet Vardiya
A1: Student | B1: Service Date | C1: Session Time | D1: Session Duration | E1: Hours | F1: Pay | G1: Units | H1: FNF | I1: Code | J1: Charged Amount | K1: User | L1: Level | M1: Note | N1: Unbilled notes | O1: Expiration Date
A2: Mohamed, Sumaya | B2: 46001 | C2: 12:00pm - 03:30pm | I2: 1/1 97153 | K2: Muse, Adna
A3: Mohamed, Sumaya | B3: 46001 | C3: 12:00pm - 03:30pm | I3: O&D 97155 | K3: Muse, Aaliya
A4: Yusuf, Khadija | B4: 46001 | C4: 01:00pm - 05:30pm | I4: 1/1 97153 | K4: Ali, Naima
A5: Yusuf 2, Khadra | B5: 46001 | C5: 01:00pm - 05:00pm | I5: 1/1 97153 | K5: Noor, Kamilo
A6: Yusuf, Khadija | B6: 46001 | C6: 01:00pm - 04:00pm | I6: O&D 97155 | K6: Muse, Ayni
A7: Abdulkadir, Nadra | B7: 46001 | C7: 01:30pm - 06:30pm | I7: 1/1 97153 | K7: Ali, Amira
A8: Abdulkadir, Nadra | B8: 46001 | C8: 01:30pm - 04:30pm | I8: O&D 97155 | K8: mohamed, Madar
A9: Kadir, Hamdi | B9: 46001 | C9: 02:00pm - 05:00pm | I9: 1/1 97153 | K9: Hashi, Ridwan
A10: Kadir, Hamdi | B10: 46001 | C10: 03:30pm - 05:00pm | I10: O&D 97155 | K10: Muse, Adna
A11: Abdulkadir, Nadra | B11: 46002 | C11: 11:30am - 06:30pm | I11: 1/1 97153 | K11: Ali, Nasteho
A12: Abdulkadir, Nadra | B12: 46002 | C12: 11:30am - 02:30pm | I12: O&D 97155 | K12: mohamed, Madar
A13: Yusuf, Khadija | B13: 46002 | C13: 01:00pm - 06:00pm | I13: 1/1 97153 | K13: Ran, Sameya
... A281: Abdi, Ahmed | B281: 46014 | C281: 06:00pm - 08:00pm | I281: O&D 97155 | K281: Muse, Adna

Sheet Note
A1: Student | B1: Service Date | C1: Session Time | D1: Session Duration | E1: Hours | F1: Pay | G1: Units | H1: FNF | I1: Code | J1: Charged Amount | K1: User | L1: Level | M1: Note | N1: Unbilled notes | O1: Expiration Date
A2: Abdi, Ahmed | B2: 46014 | C2: 06:00 PM - 08:00 PM | D2: 02:00 | E2: =HOUR(D2)+MINUTE(D2)/100 | F2: =ROUND(INT(E2) + (E2 - INT(E2)) * 100 / 60, 2) | G2: =E2*4 | H2: =LET(total, INT(E2)*60 + (E2-INT(E2))*100, blocks, QUOTIENT(total, 15), extra, MOD(total, 15), units, blocks + IF(extra>=8, 1, 0), units) | J2: =IF(L2="Level 1", VLOOKUP(I2, UserCodes!E:F, 2, FALSE) * H2, IF(L2="Level 2", VLOOKUP(I2, UserCodes!E:F, 2, FALSE) * H2 * 0.8, 0)) | K2: Muse, Adna | L2: =VLOOKUP(K2, UserCodes!A:B, 2, FALSE)
A3: Abdi, Ahmed | B3: 46013 | C3: 03:00 PM - 08:00 PM | D3: 05:00 | E3: =HOUR(D3)+MINUTE(D3)/100 | F3: =ROUND(INT(E3) + (E3 - INT(E3)) * 100 / 60, 2) | G3: =E3*4 | H3: =LET(total, INT(E3)*60 + (E3-INT(E3))*100, blocks, QUOTIENT(total, 15), extra, MOD(total, 15), units, blocks + IF(extra>=8, 1, 0), units) | J3: =IF(L3="Level 1", VLOOKUP(I3, UserCodes!E:F, 2, FALSE) * H3, IF(L3="Level 2", VLOOKUP(I3, UserCodes!E:F, 2, FALSE) * H3 * 0.8, 0)) | K3: Barqab, Mushtaq | L3: =VLOOKUP(K3, UserCodes!A:B, 2, FALSE)
A4: Abdi, Ahmed | B4: 46011 | C4: 02:32 PM - 06:00 PM | D4: 03:28 | E4: =HOUR(D4)+MINUTE(D4)/100 | F4: =ROUND(INT(E4) + (E4 - INT(E4)) * 100 / 60, 2) | G4: =E4*4 | H4: =LET(total, INT(E4)*60 + (E4-INT(E4))*100, blocks, QUOTIENT(total, 15), extra, MOD(total, 15), units, blocks + IF(extra>=8, 1, 0), units) | J4: =IF(L4="Level 1", VLOOKUP(I4, UserCodes!E:F, 2, FALSE) * H4, IF(L4="Level 2", VLOOKUP(I4, UserCodes!E:F, 2, FALSE) * H4 * 0.8, 0)) | K4: Omar, Mohamed | L4: =VLOOKUP(K4, UserCodes!A:B, 2, FALSE)
A5: Abdi, Ahmed | B5: 46011 | C5: 10:00 AM - 02:02 PM | D5: 04:02 | E5: =HOUR(D5)+MINUTE(D5)/100 | F5: =ROUND(INT(E5) + (E5 - INT(E5)) * 100 / 60, 2) | G5: =E5*4 | H5: =LET(total, INT(E5)*60 + (E5-INT(E5))*100, blocks, QUOTIENT(total, 15), extra, MOD(total, 15), units, blocks + IF(extra>=8, 1, 0), units) | J5: =IF(L5="Level 1", VLOOKUP(I5, UserCodes!E:F, 2, FALSE) * H5, IF(L5="Level 2", VLOOKUP(I5, UserCodes!E:F, 2, FALSE) * H5 * 0.8, 0)) | K5: Omar, Mohamed | L5: =VLOOKUP(K5, UserCodes!A:B, 2, FALSE)
A6: Abdi, Ahmed | B6: 46010 | C6: 03:00 PM - 08:00 PM | D6: 05:00 | E6: =HOUR(D6)+MINUTE(D6)/100 | F6: =ROUND(INT(E6) + (E6 - INT(E6)) * 100 / 60, 2) | G6: =E6*4 | H6: =LET(total, INT(E6)*60 + (E6-INT(E6))*100, blocks, QUOTIENT(total, 15), extra, MOD(total, 15), units, blocks + IF(extra>=8, 1, 0), units) | J6: =IF(L6="Level 1", VLOOKUP(I6, UserCodes!E:F, 2, FALSE) * H6, IF(L6="Level 2", VLOOKUP(I6, UserCodes!E:F, 2, FALSE) * H6 * 0.8, 0)) | K6: Ibrahim, Ahmed | L6: =VLOOKUP(K6, UserCodes!A:B, 2, FALSE)
A7: Abdi, Ahmed | B7: 46009 | C7: 03:00 PM - 08:00 PM | D7: 05:00 | E7: =HOUR(D7)+MINUTE(D7)/100 | F7: =ROUND(INT(E7) + (E7 - INT(E7)) * 100 / 60, 2) | G7: =E7*4 | H7: =LET(total, INT(E7)*60 + (E7-INT(E7))*100, blocks, QUOTIENT(total, 15), extra, MOD(total, 15), units, blocks + IF(extra>=8, 1, 0), units) | J7: =IF(L7="Level 1", VLOOKUP(I7, UserCodes!E:F, 2, FALSE) * H7, IF(L7="Level 2", VLOOKUP(I7, UserCodes!E:F, 2, FALSE) * H7 * 0.8, 0)) | K7: Ibrahim, Ahmed | L7: =VLOOKUP(K7, UserCodes!A:B, 2, FALSE)
A8: Abdi, Ahmed | B8: 46009 | C8: 03:00 PM - 06:00 PM | D8: 03:00 | E8: =HOUR(D8)+MINUTE(D8)/100 | F8: =ROUND(INT(E8) + (E8 - INT(E8)) * 100 / 60, 2) | G8: =E8*4 | H8: =LET(total, INT(E8)*60 + (E8-INT(E8))*100, blocks, QUOTIENT(total, 15), extra, MOD(total, 15), units, blocks + IF(extra>=8, 1, 0), units) | J8: =IF(L8="Level 1", VLOOKUP(I8, UserCodes!E:F, 2, FALSE) * H8, IF(L8="Level 2", VLOOKUP(I8, UserCodes!E:F, 2, FALSE) * H8 * 0.8, 0)) | K8: Muse, Adna | L8: =VLOOKUP(K8, UserCodes!A:B, 2, FALSE)
A9: Abdi, Ahmed | B9: 46008 | C9: 05:00 PM - 08:00 PM | D9: 03:00 | E9: =HOUR(D9)+MINUTE(D9)/100 | F9: =ROUND(INT(E9) + (E9 - INT(E9)) * 100 / 60, 2) | G9: =E9*4 | H9: =LET(total, INT(E9)*60 + (E9-INT(E9))*100, blocks, QUOTIENT(total, 15), extra, MOD(total, 15), units, blocks + IF(extra>=8, 1, 0), units) | J9: =IF(L9="Level 1", VLOOKUP(I9, UserCodes!E:F, 2, FALSE) * H9, IF(L9="Level 2", VLOOKUP(I9, UserCodes!E:F, 2, FALSE) * H9 * 0.8, 0)) | K9: Muse, Adna | L9: =VLOOKUP(K9, UserCodes!A:B, 2, FALSE)
A10: Abdi, Ahmed | B10: 46008 | C10: 03:00 PM - 08:00 PM | D10: 05:00 | E10: =HOUR(D10)+MINUTE(D10)/100 | F10: =ROUND(INT(E10) + (E10 - INT(E10)) * 100 / 60, 2) | G10: =E10*4 | H10: =LET(total, INT(E10)*60 + (E10-INT(E10))*100, blocks, QUOTIENT(total, 15), extra, MOD(total, 15), units, blocks + IF(extra>=8, 1, 0), units) | J10: =IF(L10="Level 1", VLOOKUP(I10, UserCodes!E:F, 2, FALSE) * H10, IF(L10="Level 2", VLOOKUP(I10, UserCodes!E:F, 2, FALSE) * H10 * 0.8, 0)) | K10: Ibrahim, Ahmed | L10: =VLOOKUP(K10, UserCodes!A:B, 2, FALSE)
A11: Abdi, Ahmed | B11: 46007 | C11: 06:00 PM - 08:00 PM | D11: 02:00 | E11: =HOUR(D11)+MINUTE(D11)/100 | F11: =ROUND(INT(E11) + (E11 - INT(E11)) * 100 / 60, 2) | G11: =E11*4 | H11: =LET(total, INT(E11)*60 + (E11-INT(E11))*100, blocks, QUOTIENT(total, 15), extra, MOD(total, 15), units, blocks + IF(extra>=8, 1, 0), units) | J11: =IF(L11="Level 1", VLOOKUP(I11, UserCodes!E:F, 2, FALSE) * H11, IF(L11="Level 2", VLOOKUP(I11, UserCodes!E:F, 2, FALSE) * H11 * 0.8, 0)) | K11: Muse, Adna | L11: =VLOOKUP(K11, UserCodes!A:B, 2, FALSE)
A12: Abdi, Ahmed | B12: 46007 | C12: 02:15 PM - 08:00 PM | D12: 05:45 | E12: =HOUR(D12)+MINUTE(D12)/100 | F12: =ROUND(INT(E12) + (E12 - INT(E12)) * 100 / 60, 2) | G12: =E12*4 | H12: =LET(total, INT(E12)*60 + (E12-INT(E12))*100, blocks, QUOTIENT(total, 15), extra, MOD(total, 15), units, blocks + IF(extra>=8, 1, 0), units) | J12: =IF(L12="Level 1", VLOOKUP(I12, UserCodes!E:F, 2, FALSE) * H12, IF(L12="Level 2", VLOOKUP(I12, UserCodes!E:F, 2, FALSE) * H12 * 0.8, 0)) | K12: Mohamed, Samsam | L12: =VLOOKUP(K12, UserCodes!A:B, 2, FALSE)
A13: Abdi, Ahmed | B13: 46006 | C13: 03:00 PM - 06:00 PM | D13: 03:00 | E13: =HOUR(D13)+MINUTE(D13)/100 | F13: =ROUND(INT(E13) + (E13 - INT(E13)) * 100 / 60, 2) | G13: =E13*4 | H13: =LET(total, INT(E13)*60 + (E13-INT(E13))*100, blocks, QUOTIENT(total, 15), extra, MOD(total, 15), units, blocks + IF(extra>=8, 1, 0), units) | J13: =IF(L13="Level 1", VLOOKUP(I13, UserCodes!E:F, 2, FALSE) * H13, IF(L13="Level 2", VLOOKUP(I13, UserCodes!E:F, 2, FALSE) * H13 * 0.8, 0)) | K13: Mohamed, Madar | L13: =VLOOKUP(K13, UserCodes!A:B, 2, FALSE)
... A303: Yusuf, Khadija | B303: 46001 | C303: 01:00 PM - 05:30 PM | D303: 04:30 | E303: =HOUR(D303)+MINUTE(D303)/100 | F303: =ROUND(INT(E303) + (E303 - INT(E303)) * 100 / 60, 2) | G303: =E303*4 | H303: =LET(total, INT(E303)*60 + (E303-INT(E303))*100, blocks, QUOTIENT(total, 15), extra, MOD(total, 15), units, blocks + IF(extra>=8, 1, 0), units) | J303: =IF(L303="Level 1", VLOOKUP(I303, UserCodes!E:F, 2, FALSE) * H303, IF(L303="Level 2", VLOOKUP(I303, UserCodes!E:F, 2, FALSE) * H303 * 0.8, 0)) | K303: Ali, Naima | L303: =VLOOKUP(K303, UserCodes!A:B, 2, FALSE)

Sheet UserCodes
A1: User | B1: Level | C1: C | D1: D | E1: Code | F1: Price
A2: Abduallahi, Ikraan | B2: Level 2 | E2: 97151 | F2: 50.11
A3: Abdulle, Suweda | B3: Level 2 | E3: PM | F3: 94.8
A4: Abdulle, Zamzam | B4: Level 2 | E4: T1024 | F4: 112.67
A5: Abdurahman, Yasmin | B5: Level 2 | E5: 1/1 97153 | F5: 20.17
A6: Ahmed, Jama | B6: Level 1 | E6: 97154 | F6: 6.72
A7: ALI, AMIRA | B7: Level 2 | E7: 0373T | F7: 24.19
A8: Ali, Naima | B8: Level 2 | E8: O&D 97155 | F8: 20.17
A9: Ali, Nasteho | B9: Level 2 | E9: FT | F9: 20.17
A10: Barack, Sara | B10: Level 2 | E10: 97157 | F10: 6.72
A11: Barqab, Mushtaq | B11: Level 2 | E11: H0046 | F11: 0.52
A12: Bello, Hiqmat | B12: Level 1
A13: Hashi, Ridwan | B13: Level 2
A14: Jama, Sara | B14: Level 2
A15: Khalif, Muna | B15: Level 1
A16: Mohamed, Meymun | B16: Level 1
A17: Muse, Aaliya | B17: Level 2
A18: Muse, Adna | B18: Level 2
A19: Muse, Ayni | B19: Level 2
A20: Noor, Kamilo | B20: Level 1
A21: Omar, Saido | B21: Level 1
A22: Ran, Sameya | B22: Level 2
A23: Kounlavouth, Roselie | B23: Level 1
... A39: Ibrahim, Ahmed | B39: Level 1

Sheet Full Students
A1: Student | B1: Service Date | C1: Session Time | D1: Session Duration | E1: Hours | F1: Pay | G1: Units | H1: FNF | I1: Code | J1: Charged Amount | K1: User | L1: Level | M1: Note | N1: Unbilled notes | O1: Expiration Date
A2: Abdulkadir, Nadra | B2: 46001 | C2: 01:00 PM - 03:00 PM | D2: 02:00 | E2: =HOUR(D2)+MINUTE(D2)/100 | F2: =ROUND(INT(E2) + (E2 - INT(E2)) * 100 / 60, 2) | G2: =E2*4 | H2: =LET(total, INT(E2)*60 + (E2-INT(E2))*100, blocks, QUOTIENT(total, 15), extra, MOD(total, 15), units, blocks + IF(extra>=8, 1, 0), units) | I2: O&D 97155 | J2: =IF(L2="Level 1", VLOOKUP(I2, UserCodes!E:F, 2, FALSE) * H2, IF(L2="Level 2", VLOOKUP(I2, UserCodes!E:F, 2, FALSE) * H2 * 0.8, 0)) | K2: Mohamed, Madar | L2: =VLOOKUP(K2, UserCodes!A:B, 2, FALSE)
A3: Abdulkadir, Nadra | B3: 46001 | C3: 01:30 PM - 06:30 PM | D3: 05:00 | E3: =HOUR(D3)+MINUTE(D3)/100 | F3: =ROUND(INT(E3) + (E3 - INT(E3)) * 100 / 60, 2) | G3: =E3*4 | H3: =LET(total, INT(E3)*60 + (E3-INT(E3))*100, blocks, QUOTIENT(total, 15), extra, MOD(total, 15), units, blocks + IF(extra>=8, 1, 0), units) | I3: 1/1 97153 | J3: =IF(L3="Level 1", VLOOKUP(I3, UserCodes!E:F, 2, FALSE) * H3, IF(L3="Level 2", VLOOKUP(I3, UserCodes!E:F, 2, FALSE) * H3 * 0.8, 0)) | K3: ALI, AMIRA | L3: =VLOOKUP(K3, UserCodes!A:B, 2, FALSE)
A4: Abdulkadir, Nadra | B4: 46001 | C4: 01:30 PM - 03:50 PM | D4: 02:20 | E4: =HOUR(D4)+MINUTE(D4)/100 | F4: =ROUND(INT(E4) + (E4 - INT(E4)) * 100 / 60, 2) | G4: =E4*4 | H4: =LET(total, INT(E4)*60 + (E4-INT(E4))*100, blocks, QUOTIENT(total, 15), extra, MOD(total, 15), units, blocks + IF(extra>=8, 1, 0), units) | J4: =IF(L4="Level 1", VLOOKUP(I4, UserCodes!E:F, 2, FALSE) * H4, IF(L4="Level 2", VLOOKUP(I4, UserCodes!E:F, 2, FALSE) * H4 * 0.8, 0)) | K4: Ahmed, Jama | L4: =VLOOKUP(K4, UserCodes!A:B, 2, FALSE) | M4: No schedule
A5: Abdulkadir, Nadra | B5: 46001 | C5: 01:30 PM - 05:00 PM | D5: 03:30 | E5: =HOUR(D5)+MINUTE(D5)/100 | F5: =ROUND(INT(E5) + (E5 - INT(E5)) * 100 / 60, 2) | G5: =E5*4 | H5: =LET(total, INT(E5)*60 + (E5-INT(E5))*100, blocks, QUOTIENT(total, 15), extra, MOD(total, 15), units, blocks + IF(extra>=8, 1, 0), units) | I5: O&D 97155 | J5: =IF(L5="Level 1", VLOOKUP(I5, UserCodes!E:F, 2, FALSE) * H5, IF(L5="Level 2", VLOOKUP(I5, UserCodes!E:F, 2, FALSE) * H5 * 0.8, 0)) | K5: Mohamed, Madar | L5: =VLOOKUP(K5, UserCodes!A:B, 2, FALSE)
A6: Yusuf, Khadija | B6: 46001 | C6: 01:00 PM - 05:30 PM | D6: 04:30 | E6: =HOUR(D6)+MINUTE(D6)/100 | F6: =ROUND(INT(E6) + (E6 - INT(E6)) * 100 / 60, 2) | G6: =E6*4 | H6: =LET(total, INT(E6)*60 + (E6-INT(E6))*100, blocks, QUOTIENT(total, 15), extra, MOD(total, 15), units, blocks + IF(extra>=8, 1, 0), units) | I6: 1/1 97153 | J6: =IF(L6="Level 1", VLOOKUP(I6, UserCodes!E:F, 2, FALSE) * H6, IF(L6="Level 2", VLOOKUP(I6, UserCodes!E:F, 2, FALSE) * H6 * 0.8, 0)) | K6: Ali, Naima | L6: =VLOOKUP(K6, UserCodes!A:B, 2, FALSE)
A7: Kadir, Hamdi | B7: 46001 | C7: 02:00 PM - 05:00 PM | D7: 03:00 | E7: =HOUR(D7)+MINUTE(D7)/100 | F7: =ROUND(INT(E7) + (E7 - INT(E7)) * 100 / 60, 2) | G7: =E7*4 | H7: =LET(total, INT(E7)*60 + (E7-INT(E7))*100, blocks, QUOTIENT(total, 15), extra, MOD(total, 15), units, blocks + IF(extra>=8, 1, 0), units) | I7: 1/1 97153 | J7: =IF(L7="Level 1", VLOOKUP(I7, UserCodes!E:F, 2, FALSE) * H7, IF(L7="Level 2", VLOOKUP(I7, UserCodes!E:F, 2, FALSE) * H7 * 0.8, 0)) | K7: Hashi, Ridwan | L7: =VLOOKUP(K7, UserCodes!A:B, 2, FALSE)
A8: Mohamed, Sumaya | B8: 46001 | C8: 12:30 PM - 03:30 PM | D8: 03:00 | E8: =HOUR(D8)+MINUTE(D8)/100 | F8: =ROUND(INT(E8) + (E8 - INT(E8)) * 100 / 60, 2) | G8: =E8*4 | H8: =LET(total, INT(E8)*60 + (E8-INT(E8))*100, blocks, QUOTIENT(total, 15), extra, MOD(total, 15), units, blocks + IF(extra>=8, 1, 0), units) | I8: 1/1 97153 | J8: =IF(L8="Level 1", VLOOKUP(I8, UserCodes!E:F, 2, FALSE) * H8, IF(L8="Level 2", VLOOKUP(I8, UserCodes!E:F, 2, FALSE) * H8 * 0.8, 0)) | K8: Muse, Adna | L8: =VLOOKUP(K8, UserCodes!A:B, 2, FALSE)
A9: Kadir, Hamdi | B9: 46001 | C9: 03:30 PM - 05:00 PM | D9: 01:30 | E9: =HOUR(D9)+MINUTE(D9)/100 | F9: =ROUND(INT(E9) + (E9 - INT(E9)) * 100 / 60, 2) | G9: =E9*4 | H9: =LET(total, INT(E9)*60 + (E9-INT(E9))*100, blocks, QUOTIENT(total, 15), extra, MOD(total, 15), units, blocks + IF(extra>=8, 1, 0), units) | I9: O&D 97155 | J9: =IF(L9="Level 1", VLOOKUP(I9, UserCodes!E:F, 2, FALSE) * H9, IF(L9="Level 2", VLOOKUP(I9, UserCodes!E:F, 2, FALSE) * H9 * 0.8, 0)) | K9: Muse, Adna | L9: =VLOOKUP(K9, UserCodes!A:B, 2, FALSE)
A10: Yusuf, Khadija | B10: 46001 | C10: 01:00 PM - 04:00 PM | D10: 03:00 | E10: =HOUR(D10)+MINUTE(D10)/100 | F10: =ROUND(INT(E10) + (E10 - INT(E10)) * 100 / 60, 2) | G10: =E10*4 | H10: =LET(total, INT(E10)*60 + (E10-INT(E10))*100, blocks, QUOTIENT(total, 15), extra, MOD(total, 15), units, blocks + IF(extra>=8, 1, 0), units) | I10: O&D 97155 | J10: =IF(L10="Level 1", VLOOKUP(I10, UserCodes!E:F, 2, FALSE) * H10, IF(L10="Level 2", VLOOKUP(I10, UserCodes!E:F, 2, FALSE) * H10 * 0.8, 0)) | K10: Muse, Ayni | L10: =VLOOKUP(K10, UserCodes!A:B, 2, FALSE)
A11: Yusuf 2, Khadra | B11: 46001 | C11: 01:00 PM - 05:30 PM | D11: 04:30 | E11: =HOUR(D11)+MINUTE(D11)/100 | F11: =ROUND(INT(E11) + (E11 - INT(E11)) * 100 / 60, 2) | G11: =E11*4 | H11: =LET(total, INT(E11)*60 + (E11-INT(E11))*100, blocks, QUOTIENT(total, 15), extra, MOD(total, 15), units, blocks + IF(extra>=8, 1, 0), units) | I11: 1/1 97153 | J11: =IF(L11="Level 1", VLOOKUP(I11, UserCodes!E:F, 2, FALSE) * H11, IF(L11="Level 2", VLOOKUP(I11, UserCodes!E:F, 2, FALSE) * H11 * 0.8, 0)) | K11: Noor, Kamilo | L11: =VLOOKUP(K11, UserCodes!A:B, 2, FALSE)
A12: Abdi, Samira | B12: 46001 | C12: 10:00 AM - 12:30 PM | D12: 02:30 | E12: =HOUR(D12)+MINUTE(D12)/100 | F12: =ROUND(INT(E12) + (E12 - INT(E12)) * 100 / 60, 2) | G12: =E12*4 | H12: =LET(total, INT(E12)*60 + (E12-INT(E12))*100, blocks, QUOTIENT(total, 15), extra, MOD(total, 15), units, blocks + IF(extra>=8, 1, 0), units) | J12: =IF(L12="Level 1", VLOOKUP(I12, UserCodes!E:F, 2, FALSE) * H12, IF(L12="Level 2", VLOOKUP(I12, UserCodes!E:F, 2, FALSE) * H12 * 0.8, 0)) | K12: Ahmed, Jama | L12: =VLOOKUP(K12, UserCodes!A:B, 2, FALSE) | M12: No schedule
A13: Mohamed, Sumaya | B13: 46001 | C13: 12:30 PM - 03:30 PM | D13: 03:00 | E13: =HOUR(D13)+MINUTE(D13)/100 | F13: =ROUND(INT(E13) + (E13 - INT(E13)) * 100 / 60, 2) | G13: =E13*4 | H13: =LET(total, INT(E13)*60 + (E13-INT(E13))*100, blocks, QUOTIENT(total, 15), extra, MOD(total, 15), units, blocks + IF(extra>=8, 1, 0), units) | I13: O&D 97155 | J13: =IF(L13="Level 1", VLOOKUP(I13, UserCodes!E:F, 2, FALSE) * H13, IF(L13="Level 2", VLOOKUP(I13, UserCodes!E:F, 2, FALSE) * H13 * 0.8, 0)) | K13: Muse, Aaliya | L13: =VLOOKUP(K13, UserCodes!A:B, 2, FALSE)
A14: Abdi, Mohamed | B14: 46002 | C14: 03:00 PM - 08:00 PM | D14: 05:00 | E14: =HOUR(D14)+MINUTE(D14)/100 | F14: =ROUND(INT(E14) + (E14 - INT(E14)) * 100 / 60, 2) | G14: =E14*4 | H14: =LET(total, INT(E14)*60 + (E14-INT(E14))*100, blocks, QUOTIENT(total, 15), extra, MOD(total, 15), units, blocks + IF(extra>=8, 1, 0), units) | I14: 1/1 97153 | J14: =IF(L14="Level 1", VLOOKUP(I14, UserCodes!E:F, 2, FALSE) * H14, IF(L14="Level 2", VLOOKUP(I14, UserCodes!E:F, 2, FALSE) * H14 * 0.8, 0)) | K14: Omar, Mohamed | L14: =VLOOKUP(K14, UserCodes!A:B, 2, FALSE)
A15: Abdi, Mohamed | B15: 46002 | C15: 04:00 PM - 07:00 PM | D15: 03:00 | E15: =HOUR(D15)+MINUTE(D15)/100 | F15: =ROUND(INT(E15) + (E15 - INT(E15)) * 100 / 60, 2) | G15: =E15*4 | H15: =LET(total, INT(E15)*60 + (E15-INT(E15))*100, blocks, QUOTIENT(total, 15), extra, MOD(total, 15), units, blocks + IF(extra>=8, 1, 0), units) | I15: O&D 97155 | J15: =IF(L15="Level 1", VLOOKUP(I15, UserCodes!E:F, 2, FALSE) * H15, IF(L15="Level 2", VLOOKUP(I15, UserCodes!E:F, 2, FALSE) * H15 * 0.8, 0)) | K15: Hawadle, Abdiaziz | L15: =VLOOKUP(K15, UserCodes!A:B, 2, FALSE)
A16: Abdulkadir, Nadra | B16: 46002 | C16: 01:30 PM - 06:30 PM | D16: 05:00 | E16: =HOUR(D16)+MINUTE(D16)/100 | F16: =ROUND(INT(E16) + (E16 - INT(E16)) * 100 / 60, 2) | G16: =E16*4 | H16: =LET(total, INT(E16)*60 + (E16-INT(E16))*100, blocks, QUOTIENT(total, 15), extra, MOD(total, 15), units, blocks + IF(extra>=8, 1, 0), units) | I16: 1/1 97153 | J16: =IF(L16="Level 1", VLOOKUP(I16, UserCodes!E:F, 2, FALSE) * H16, IF(L16="Level 2", VLOOKUP(I16, UserCodes!E:F, 2, FALSE) * H16 * 0.8, 0)) | K16: Ali, Nasteho | L16: =VLOOKUP(K16, UserCodes!A:B, 2, FALSE)
A17: Yusuf, Khadija | B17: 46002 | C17: 01:00 PM - 06:00 PM | D17: 05:00 | E17: =HOUR(D17)+MINUTE(D17)/100 | F17: =ROUND(INT(E17) + (E17 - INT(E17)) * 100 / 60, 2) | G17: =E17*4 | H17: =LET(total, INT(E17)*60 + (E17-INT(E17))*100, blocks, QUOTIENT(total, 15), extra, MOD(total, 15), units, blocks + IF(extra>=8, 1, 0), units) | I17: 1/1 97153 | J17: =IF(L17="Level 1", VLOOKUP(I17, UserCodes!E:F, 2, FALSE) * H17, IF(L17="Level 2", VLOOKUP(I17, UserCodes!E:F, 2, FALSE) * H17 * 0.8, 0)) | K17: Ran, Sameya | L17: =VLOOKUP(K17, UserCodes!A:B, 2, FALSE)
A18: Abdi, Samira | B18: 46002 | C18: 06:30 PM - 08:00 PM | D18: 01:30 | E18: =HOUR(D18)+MINUTE(D18)/100 | F18: =ROUND(INT(E18) + (E18 - INT(E18)) * 100 / 60, 2) | G18: =E18*4 | H18: =LET(total, INT(E18)*60 + (E18-INT(E18))*100, blocks, QUOTIENT(total, 15), extra, MOD(total, 15), units, blocks + IF(extra>=8, 1, 0), units) | I18: O&D 97155 | J18: =IF(L18="Level 1", VLOOKUP(I18, UserCodes!E:F, 2, FALSE) * H18, IF(L18="Level 2", VLOOKUP(I18, UserCodes!E:F, 2, FALSE) * H18 * 0.8, 0)) | K18: Ali, Nasteho | L18: =VLOOKUP(K18, UserCodes!A:B, 2, FALSE)
A19: Abdi, Salman | B19: 46002 | C19: 03:15 PM - 08:00 PM | D19: 04:45 | E19: =HOUR(D19)+MINUTE(D19)/100 | F19: =ROUND(INT(E19) + (E19 - INT(E19)) * 100 / 60, 2) | G19: =E19*4 | H19: =LET(total, INT(E19)*60 + (E19-INT(E19))*100, blocks, QUOTIENT(total, 15), extra, MOD(total, 15), units, blocks + IF(extra>=8, 1, 0), units) | I19: 1/1 97153 | J19: =IF(L19="Level 1", VLOOKUP(I19, UserCodes!E:F, 2, FALSE) * H19, IF(L19="Level 2", VLOOKUP(I19, UserCodes!E:F, 2, FALSE) * H19 * 0.8, 0)) | K19: Mohamed, Mohamed | L19: =VLOOKUP(K19, UserCodes!A:B, 2, FALSE)
A20: Abdullahi, Abdirahman | B20: 46002 | C20: 01:00 PM - 04:00 PM | D20: 03:00 | E20: =HOUR(D20)+MINUTE(D20)/100 | F20: =ROUND(INT(E20) + (E20 - INT(E20)) * 100 / 60, 2) | G20: =E20*4 | H20: =LET(total, INT(E20)*60 + (E20-INT(E20))*100, blocks, QUOTIENT(total, 15), extra, MOD(total, 15), units, blocks + IF(extra>=8, 1, 0), units) | I20: O&D 97155 | J20: =IF(L20="Level 1", VLOOKUP(I20, UserCodes!E:F, 2, FALSE) * H20, IF(L20="Level 2", VLOOKUP(I20, UserCodes!E:F, 2, FALSE) * H20 * 0.8, 0)) | K20: Hawadle, Abdiaziz | L20: =VLOOKUP(K20, UserCodes!A:B, 2, FALSE)
A21: Abdullahi, Abdirahman | B21: 46002 | C21: 01:00 PM - 05:00 PM | D21: 04:00 | E21: =HOUR(D21)+MINUTE(D21)/100 | F21: =ROUND(INT(E21) + (E21 - INT(E21)) * 100 / 60, 2) | G21: =E21*4 | H21: =LET(total, INT(E21)*60 + (E21-INT(E21))*100, blocks, QUOTIENT(total, 15), extra, MOD(total, 15), units, blocks + IF(extra>=8, 1, 0), units) | I21: 1/1 97153 | J21: =IF(L21="Level 1", VLOOKUP(I21, UserCodes!E:F, 2, FALSE) * H21, IF(L21="Level 2", VLOOKUP(I21, UserCodes!E:F, 2, FALSE) * H21 * 0.8, 0)) | K21: ALI, AMIRA | L21: =VLOOKUP(K21, UserCodes!A:B, 2, FALSE)
A22: Abdullahi, Abdirahman | B22: 46002 | C22: 09:30 AM - 11:45 AM | D22: 02:15 | E22: =HOUR(D22)+MINUTE(D22)/100 | F22: =ROUND(INT(E22) + (E22 - INT(E22)) * 100 / 60, 2) | G22: =E22*4 | H22: =LET(total, INT(E22)*60 + (E22-INT(E22))*100, blocks, QUOTIENT(total, 15), extra, MOD(total, 15), units, blocks + IF(extra>=8, 1, 0), units) | J22: =IF(L22="Level 1", VLOOKUP(I22, UserCodes!E:F, 2, FALSE) * H22, IF(L22="Level 2", VLOOKUP(I22, UserCodes!E:F, 2, FALSE) * H22 * 0.8, 0)) | K22: Ahmed, Jama | L22: =VLOOKUP(K22, UserCodes!A:B, 2, FALSE) | M22: No schedule
A23: Abdi, Salman | B23: 46002 | C23: 04:30 PM - 06:30 PM | D23: 02:00 | E23: =HOUR(D23)+MINUTE(D23)/100 | F23: =ROUND(INT(E23) + (E23 - INT(E23)) * 100 / 60, 2) | G23: =E23*4 | H23: =LET(total, INT(E23)*60 + (E23-INT(E23))*100, blocks, QUOTIENT(total, 15), extra, MOD(total, 15), units, blocks + IF(extra>=8, 1, 0), units) | I23: O&D 97155 | J23: =IF(L23="Level 1", VLOOKUP(I23, UserCodes!E:F, 2, FALSE) * H23, IF(L23="Level 2", VLOOKUP(I23, UserCodes!E:F, 2, FALSE) * H23 * 0.8, 0)) | K23: Mohamed, Madar | L23: =VLOOKUP(K23, UserCodes!A:B, 2, FALSE)
A24: Ali, Saami | B24: 46002 | C24: 05:00 PM - 08:00 PM | D24: 03:00 | E24: =HOUR(D24)+MINUTE(D24)/100 | F24: =ROUND(INT(E24) + (E24 - INT(E24)) * 100 / 60, 2) | G24: =E24*4 | H24: =LET(total, INT(E24)*60 + (E24-INT(E24))*100, blocks, QUOTIENT(total, 15), extra, MOD(total, 15), units, blocks + IF(extra>=8, 1, 0), units) | I24: O&D 97155 | J24: =IF(L24="Level 1", VLOOKUP(I24, UserCodes!E:F, 2, FALSE) * H24, IF(L24="Level 2", VLOOKUP(I24, UserCodes!E:F, 2, FALSE) * H24 * 0.8, 0)) | K24: Ibrahim, Ahmed | L24: =VLOOKUP(K24, UserCodes!A:B, 2, FALSE)
A25: Abdi, Safia | B25: 46002 | C25: 05:00 PM - 08:00 PM | D25: 03:00 | E25: =HOUR(D25)+MINUTE(D25)/100 | F25: =ROUND(INT(E25) + (E25 - INT(E25)) * 100 / 60, 2) | G25: =E25*4 | H25: =LET(total, INT(E25)*60 + (E25-INT(E25))*100, blocks, QUOTIENT(total, 15), extra, MOD(total, 15), units, blocks + IF(extra>=8, 1, 0), units) | I25: O&D 97155 | J25: =IF(L25="Level 1", VLOOKUP(I25, UserCodes!E:F, 2, FALSE) * H25, IF(L25="Level 2", VLOOKUP(I25, UserCodes!E:F, 2, FALSE) * H25 * 0.8, 0)) | K25: Muse, Adna | L25: =VLOOKUP(K25, UserCodes!A:B, 2, FALSE)
A26: Abdulkadir, Nadra | B26: 46002 | C26: 11:30am - 02:30pm | E26: =HOUR(D26)+MINUTE(D26)/100 | F26: =ROUND(INT(E26) + (E26 - INT(E26)) * 100 / 60, 2) | G26: =E26*4 | H26: =LET(total, INT(E26)*60 + (E26-INT(E26))*100, blocks, QUOTIENT(total, 15), extra, MOD(total, 15), units, blocks + IF(extra>=8, 1, 0), units) | I26: O&D 97155 | J26: =IF(L26="Level 1", VLOOKUP(I26, UserCodes!E:F, 2, FALSE) * H26, IF(L26="Level 2", VLOOKUP(I26, UserCodes!E:F, 2, FALSE) * H26 * 0.8, 0)) | K26: mohamed, Madar | L26: =VLOOKUP(K26, UserCodes!A:B, 2, FALSE) | M26: No note
A27: Yusuf 2, Khadra | B27: 46002 | C27: 01:00 PM - 03:00 PM | D27: 02:00 | E27: =HOUR(D27)+MINUTE(D27)/100 | F27: =ROUND(INT(E27) + (E27 - INT(E27)) * 100 / 60, 2) | G27: =E27*4 | H27: =LET(total, INT(E27)*60 + (E27-INT(E27))*100, blocks, QUOTIENT(total, 15), extra, MOD(total, 15), units, blocks + IF(extra>=8, 1, 0), units) | I27: O&D 97155 | J27: =IF(L27="Level 1", VLOOKUP(I27, UserCodes!E:F, 2, FALSE) * H27, IF(L27="Level 2", VLOOKUP(I27, UserCodes!E:F, 2, FALSE) * H27 * 0.8, 0)) | K27: Muse, Ayni | L27: =VLOOKUP(K27, UserCodes!A:B, 2, FALSE)
A28: Yusuf 2, Khadra | B28: 46002 | C28: 01:00 PM - 06:00 PM | D28: 05:00 | E28: =HOUR(D28)+MINUTE(D28)/100 | F28: =ROUND(INT(E28) + (E28 - INT(E28)) * 100 / 60, 2) | G28: =E28*4 | H28: =LET(total, INT(E28)*60 + (E28-INT(E28))*100, blocks, QUOTIENT(total, 15), extra, MOD(total, 15), units, blocks + IF(extra>=8, 1, 0), units) | I28: 1/1 97153 | J28: =IF(L28="Level 1", VLOOKUP(I28, UserCodes!E:F, 2, FALSE) * H28, IF(L28="Level 2", VLOOKUP(I28, UserCodes!E:F, 2, FALSE) * H28 * 0.8, 0)) | K28: Hashi, Ridwan | L28: =VLOOKUP(K28, UserCodes!A:B, 2, FALSE)
A29: Sulub, Sharmake | B29: 46002 | C29: 04:00 PM - 08:00 PM | D29: 04:00 | E29: =HOUR(D29)+MINUTE(D29)/100 | F29: =ROUND(INT(E29) + (E29 - INT(E29)) * 100 / 60, 2) | G29: =E29*4 | H29: =LET(total, INT(E29)*60 + (E29-INT(E29))*100, blocks, QUOTIENT(total, 15), extra, MOD(total, 15), units, blocks + IF(extra>=8, 1, 0), units) | I29: 1/1 97153 | J29: =IF(L29="Level 1", VLOOKUP(I29, UserCodes!E:F, 2, FALSE) * H29, IF(L29="Level 2", VLOOKUP(I29, UserCodes!E:F, 2, FALSE) * H29 * 0.8, 0)) | K29: Osman, Basra | L29: =VLOOKUP(K29, UserCodes!A:B, 2, FALSE)
A30: Kadir, Hamdi | B30: 46002 | C30: 02:00 PM - 08:00 PM | D30: 06:00 | E30: =HOUR(D30)+MINUTE(D30)/100 | F30: =ROUND(INT(E30) + (E30 - INT(E30)) * 100 / 60, 2) | G30: =E30*4 | H30: =LET(total, INT(E30)*60 + (E30-INT(E30))*100, blocks, QUOTIENT(total, 15), extra, MOD(total, 15), units, blocks + IF(extra>=8, 1, 0), units) | I30: 1/1 97153 | J30: =IF(L30="Level 1", VLOOKUP(I30, UserCodes!E:F, 2, FALSE) * H30, IF(L30="Level 2", VLOOKUP(I30, UserCodes!E:F, 2, FALSE) * H30 * 0.8, 0)) | K30: Mohamed, Samsam | L30: =VLOOKUP(K30, UserCodes!A:B, 2, FALSE)
A31: Kadir, Hamdi | B31: 46002 | C31: 02:00 PM - 05:00 PM | D31: 03:00 | E31: =HOUR(D31)+MINUTE(D31)/100 | F31: =ROUND(INT(E31) + (E31 - INT(E31)) * 100 / 60, 2) | G31: =E31*4 | H31: =LET(total, INT(E31)*60 + (E31-INT(E31))*100, blocks, QUOTIENT(total, 15), extra, MOD(total, 15), units, blocks + IF(extra>=8, 1, 0), units) | I31: O&D 97155 | J31: =IF(L31="Level 1", VLOOKUP(I31, UserCodes!E:F, 2, FALSE) * H31, IF(L31="Level 2", VLOOKUP(I31, UserCodes!E:F, 2, FALSE) * H31 * 0.8, 0)) | K31: Muse, Adna | L31: =VLOOKUP(K31, UserCodes!A:B, 2, FALSE)
A32: Abdi, Safia | B32: 46002 | C32: 03:00 PM - 08:00 PM | D32: 05:00 | E32: =HOUR(D32)+MINUTE(D32)/100 | F32: =ROUND(INT(E32) + (E32 - INT(E32)) * 100 / 60, 2) | G32: =E32*4 | H32: =LET(total, INT(E32)*60 + (E32-INT(E32))*100, blocks, QUOTIENT(total, 15), extra, MOD(total, 15), units, blocks + IF(extra>=8, 1, 0), units) | I32: 1/1 97153 | J32: =IF(L32="Level 1", VLOOKUP(I32, UserCodes!E:F, 2, FALSE) * H32, IF(L32="Level 2", VLOOKUP(I32, UserCodes!E:F, 2, FALSE) * H32 * 0.8, 0)) | K32: Muse, Ayni | L32: =VLOOKUP(K32, UserCodes!A:B, 2, FALSE)
A33: Abdi, Samira | B33: 46002 | C33: 05:00 PM - 06:00 PM | D33: 01:00 | E33: =HOUR(D33)+MINUTE(D33)/100 | F33: =ROUND(INT(E33) + (E33 - INT(E33)) * 100 / 60, 2) | G33: =E33*4 | H33: =LET(total, INT(E33)*60 + (E33-INT(E33))*100, blocks, QUOTIENT(total, 15), extra, MOD(total, 15), units, blocks + IF(extra>=8, 1, 0), units) | J33: =IF(L33="Level 1", VLOOKUP(I33, UserCodes!E:F, 2, FALSE) * H33, IF(L33="Level 2", VLOOKUP(I33, UserCodes!E:F, 2, FALSE) * H33 * 0.8, 0)) | K33: El-Tay, Dr. Ismael | L33: =VLOOKUP(K33, UserCodes!A:B, 2, FALSE) | M33: No schedule
A34: Yusuf, Khadija | B34: 46002 | C34: 01:00 PM - 04:00 PM | D34: 03:00 | E34: =HOUR(D34)+MINUTE(D34)/100 | F34: =ROUND(INT(E34) + (E34 - INT(E34)) * 100 / 60, 2) | G34: =E34*4 | H34: =LET(total, INT(E34)*60 + (E34-INT(E34))*100, blocks, QUOTIENT(total, 15), extra, MOD(total, 15), units, blocks + IF(extra>=8, 1, 0), units) | I34: 1/1 97153 | J34: =IF(L34="Level 1", VLOOKUP(I34, UserCodes!E:F, 2, FALSE) * H34, IF(L34="Level 2", VLOOKUP(I34, UserCodes!E:F, 2, FALSE) * H34 * 0.8, 0)) | K34: Noor, Kamilo | L34: =VLOOKUP(K34, UserCodes!A:B, 2, FALSE)
A35: Jama, Khadija | B35: 46002 | C35: 04:30 PM - 08:00 PM | D35: 03:30 | E35: =HOUR(D35)+MINUTE(D35)/100 | F35: =ROUND(INT(E35) + (E35 - INT(E35)) * 100 / 60, 2) | G35: =E35*4 | H35: =LET(total, INT(E35)*60 + (E35-INT(E35))*100, blocks, QUOTIENT(total, 15), extra, MOD(total, 15), units, blocks + IF(extra>=8, 1, 0), units) | I35: 1/1 97153 | J35: =IF(L35="Level 1", VLOOKUP(I35, UserCodes!E:F, 2, FALSE) * H35, IF(L35="Level 2", VLOOKUP(I35, UserCodes!E:F, 2, FALSE) * H35 * 0.8, 0)) | K35: Noor, Kamilo | L35: =VLOOKUP(K35, UserCodes!A:B, 2, FALSE)
A36: Ali, Saami | B36: 46002 | C36: 03:50 PM - 08:00 PM | D36: 04:10 | E36: =HOUR(D36)+MINUTE(D36)/100 | F36: =ROUND(INT(E36) + (E36 - INT(E36)) * 100 / 60, 2) | G36: =E36*4 | H36: =LET(total, INT(E36)*60 + (E36-INT(E36))*100, blocks, QUOTIENT(total, 15), extra, MOD(total, 15), units, blocks + IF(extra>=8, 1, 0), units) | I36: 1/1 97153 | J36: =IF(L36="Level 1", VLOOKUP(I36, UserCodes!E:F, 2, FALSE) * H36, IF(L36="Level 2", VLOOKUP(I36, UserCodes!E:F, 2, FALSE) * H36 * 0.8, 0)) | K36: Muse, Aaliya | L36: =VLOOKUP(K36, UserCodes!A:B, 2, FALSE)
A37: Abdi, Samira | B37: 46002 | C37: 04:00 PM - 08:00 PM | D37: 04:00 | E37: =HOUR(D37)+MINUTE(D37)/100 | F37: =ROUND(INT(E37) + (E37 - INT(E37)) * 100 / 60, 2) | G37: =E37*4 | H37: =LET(total, INT(E37)*60 + (E37-INT(E37))*100, blocks, QUOTIENT(total, 15), extra, MOD(total, 15), units, blocks + IF(extra>=8, 1, 0), units) | I37: 1/1 97153 | J37: =IF(L37="Level 1", VLOOKUP(I37, UserCodes!E:F, 2, FALSE) * H37, IF(L37="Level 2", VLOOKUP(I37, UserCodes!E:F, 2, FALSE) * H37 * 0.8, 0)) | K37: Muse, Nawaal | L37: =VLOOKUP(K37, UserCodes!A:B, 2, FALSE)
A38: Abdi, Safia | B38: 46002 | C38: 01:28 PM - 03:50 PM | D38: 02:22 | E38: =HOUR(D38)+MINUTE(D38)/100 | F38: =ROUND(INT(E38) + (E38 - INT(E38)) * 100 / 60, 2) | G38: =E38*4 | H38: =LET(total, INT(E38)*60 + (E38-INT(E38))*100, blocks, QUOTIENT(total, 15), extra, MOD(total, 15), units, blocks + IF(extra>=8, 1, 0), units) | J38: =IF(L38="Level 1", VLOOKUP(I38, UserCodes!E:F, 2, FALSE) * H38, IF(L38="Level 2", VLOOKUP(I38, UserCodes!E:F, 2, FALSE) * H38 * 0.8, 0)) | K38: Ahmed, Jama | L38: =VLOOKUP(K38, UserCodes!A:B, 2, FALSE) | M38: No schedule
A39: Yusuf, Khadija | B39: 46003 | C39: 02:00 PM - 05:00 PM | D39: 03:00 | E39: =HOUR(D39)+MINUTE(D39)/100 | F39: =ROUND(INT(E39) + (E39 - INT(E39)) * 100 / 60, 2) | G39: =E39*4 | H39: =LET(total, INT(E39)*60 + (E39-INT(E39))*100, blocks, QUOTIENT(total, 15), extra, MOD(total, 15), units, blocks + IF(extra>=8, 1, 0), units) | I39: O&D 97155 | J39: =IF(L39="Level 1", VLOOKUP(I39, UserCodes!E:F, 2, FALSE) * H39, IF(L39="Level 2", VLOOKUP(I39, UserCodes!E:F, 2, FALSE) * H39 * 0.8, 0)) | K39: Noor, Kamilo | L39: =VLOOKUP(K39, UserCodes!A:B, 2, FALSE)
A40: Abdi, Samira | B40: 46003 | C40: 04:00 PM - 08:00 PM | D40: 04:00 | E40: =HOUR(D40)+MINUTE(D40)/100 | F40: =ROUND(INT(E40) + (E40 - INT(E40)) * 100 / 60, 2) | G40: =E40*4 | H40: =LET(total, INT(E40)*60 + (E40-INT(E40))*100, blocks, QUOTIENT(total, 15), extra, MOD(total, 15), units, blocks + IF(extra>=8, 1, 0), units) | I40: 1/1 97153 | J40: =IF(L40="Level 1", VLOOKUP(I40, UserCodes!E:F, 2, FALSE) * H40, IF(L40="Level 2", VLOOKUP(I40, UserCodes!E:F, 2, FALSE) * H40 * 0.8, 0)) | K40: Muse, Ayni | L40: =VLOOKUP(K40, UserCodes!A:B, 2, FALSE)
...

Sheet Abdulkadir, Nadra
A1: Student | B1: Service Date | C1: Session Time | D1: Session Duration | E1: Hours | F1: Pay | G1: Units | H1: FNF | I1: Code | J1: Charged Amount | K1: User | L1: Level | M1: Note | N1: Unbilled notes | O1: Expiration Date
A2: Abdulkadir, Nadra | B2: 46001 | C2: 01:00 PM - 03:00 PM | D2: 02:00 | E2: =HOUR(D2)+MINUTE(D2)/100 | F2: =ROUND(INT(E2) + (E2 - INT(E2)) * 100 / 60, 2) | G2: =E2*4 | H2: =LET(total, INT(E2)*60 + (E2-INT(E2))*100, blocks, QUOTIENT(total, 15), extra, MOD(total, 15), units, blocks + IF(extra>=8, 1, 0), units) | I2: O&D 97155 | J2: =IF(L2="Level 1", VLOOKUP(I2, UserCodes!E:F, 2, FALSE) * H2, IF(L2="Level 2", VLOOKUP(I2, UserCodes!E:F, 2, FALSE) * H2 * 0.8, 0)) | K2: Mohamed, Madar | L2: =VLOOKUP(K2, UserCodes!A:B, 2, FALSE)
A3: Abdulkadir, Nadra | B3: 46001 | C3: 01:30 PM - 06:30 PM | D3: 05:00 | E3: =HOUR(D3)+MINUTE(D3)/100 | F3: =ROUND(INT(E3) + (E3 - INT(E3)) * 100 / 60, 2) | G3: =E3*4 | H3: =LET(total, INT(E3)*60 + (E3-INT(E3))*100, blocks, QUOTIENT(total, 15), extra, MOD(total, 15), units, blocks + IF(extra>=8, 1, 0), units) | I3: 1/1 97153 | J3: =IF(L3="Level 1", VLOOKUP(I3, UserCodes!E:F, 2, FALSE) * H3, IF(L3="Level 2", VLOOKUP(I3, UserCodes!E:F, 2, FALSE) * H3 * 0.8, 0)) | K3: ALI, AMIRA | L3: =VLOOKUP(K3, UserCodes!A:B, 2, FALSE)
A4: Abdulkadir, Nadra | B4: 46001 | C4: 01:30 PM - 03:50 PM | D4: 02:20 | E4: =HOUR(D4)+MINUTE(D4)/100 | F4: =ROUND(INT(E4) + (E4 - INT(E4)) * 100 / 60, 2) | G4: =E4*4 | H4: =LET(total, INT(E4)*60 + (E4-INT(E4))*100, blocks, QUOTIENT(total, 15), extra, MOD(total, 15), units, blocks + IF(extra>=8, 1, 0), units) | J4: =IF(L4="Level 1", VLOOKUP(I4, UserCodes!E:F, 2, FALSE) * H4, IF(L4="Level 2", VLOOKUP(I4, UserCodes!E:F, 2, FALSE) * H4 * 0.8, 0)) | K4: Ahmed, Jama | L4: =VLOOKUP(K4, UserCodes!A:B, 2, FALSE) | M4: No schedule
A5: Abdulkadir, Nadra | B5: 46001 | C5: 01:30 PM - 05:00 PM | D5: 03:30 | E5: =HOUR(D5)+MINUTE(D5)/100 | F5: =ROUND(INT(E5) + (E5 - INT(E5)) * 100 / 60, 2) | G5: =E5*4 | H5: =LET(total, INT(E5)*60 + (E5-INT(E5))*100, blocks, QUOTIENT(total, 15), extra, MOD(total, 15), units, blocks + IF(extra>=8, 1, 0), units) | I5: O&D 97155 | J5: =IF(L5="Level 1", VLOOKUP(I5, UserCodes!E:F, 2, FALSE) * H5, IF(L5="Level 2", VLOOKUP(I5, UserCodes!E:F, 2, FALSE) * H5 * 0.8, 0)) | K5: Mohamed, Madar | L5: =VLOOKUP(K5, UserCodes!A:B, 2, FALSE)
A6: Abdulkadir, Nadra | B6: 46002 | C6: 01:30 PM - 06:30 PM | D6: 05:00 | E6: =HOUR(D6)+MINUTE(D6)/100 | F6: =ROUND(INT(E6) + (E6 - INT(E6)) * 100 / 60, 2) | G6: =E6*4 | H6: =LET(total, INT(E6)*60 + (E6-INT(E6))*100, blocks, QUOTIENT(total, 15), extra, MOD(total, 15), units, blocks + IF(extra>=8, 1, 0), units) | I6: 1/1 97153 | J6: =IF(L6="Level 1", VLOOKUP(I6, UserCodes!E:F, 2, FALSE) * H6, IF(L6="Level 2", VLOOKUP(I6, UserCodes!E:F, 2, FALSE) * H6 * 0.8, 0)) | K6: Ali, Nasteho | L6: =VLOOKUP(K6, UserCodes!A:B, 2, FALSE)
A7: Abdulkadir, Nadra | B7: 46002 | C7: 11:30am - 02:30pm | E7: =HOUR(D7)+MINUTE(D7)/100 | F7: =ROUND(INT(E7) + (E7 - INT(E7)) * 100 / 60, 2) | G7: =E7*4 | H7: =LET(total, INT(E7)*60 + (E7-INT(E7))*100, blocks, QUOTIENT(total, 15), extra, MOD(total, 15), units, blocks + IF(extra>=8, 1, 0), units) | I7: O&D 97155 | J7: =IF(L7="Level 1", VLOOKUP(I7, UserCodes!E:F, 2, FALSE) * H7, IF(L7="Level 2", VLOOKUP(I7, UserCodes!E:F, 2, FALSE) * H7 * 0.8, 0)) | K7: mohamed, Madar | L7: =VLOOKUP(K7, UserCodes!A:B, 2, FALSE) | M7: No note
A8: Abdulkadir, Nadra | B8: 46003 | C8: 01:00 PM - 04:30 PM | D8: 03:30 | E8: =HOUR(D8)+MINUTE(D8)/100 | F8: =ROUND(INT(E8) + (E8 - INT(E8)) * 100 / 60, 2) | G8: =E8*4 | H8: =LET(total, INT(E8)*60 + (E8-INT(E8))*100, blocks, QUOTIENT(total, 15), extra, MOD(total, 15), units, blocks + IF(extra>=8, 1, 0), units) | I8: O&D 97155 | J8: =IF(L8="Level 1", VLOOKUP(I8, UserCodes!E:F, 2, FALSE) * H8, IF(L8="Level 2", VLOOKUP(I8, UserCodes!E:F, 2, FALSE) * H8 * 0.8, 0)) | K8: Mohamed, Madar | L8: =VLOOKUP(K8, UserCodes!A:B, 2, FALSE)
A9: Abdulkadir, Nadra | B9: 46003 | C9: 01:30 PM - 06:30 PM | D9: 05:00 | E9: =HOUR(D9)+MINUTE(D9)/100 | F9: =ROUND(INT(E9) + (E9 - INT(E9)) * 100 / 60, 2) | G9: =E9*4 | H9: =LET(total, INT(E9)*60 + (E9-INT(E9))*100, blocks, QUOTIENT(total, 15), extra, MOD(total, 15), units, blocks + IF(extra>=8, 1, 0), units) | I9: 1/1 97153 | J9: =IF(L9="Level 1", VLOOKUP(I9, UserCodes!E:F, 2, FALSE) * H9, IF(L9="Level 2", VLOOKUP(I9, UserCodes!E:F, 2, FALSE) * H9 * 0.8, 0)) | K9: Ali, Nasteho | L9: =VLOOKUP(K9, UserCodes!A:B, 2, FALSE)
A10: Abdulkadir, Nadra | B10: 46004 | C10: 12:30 PM - 05:00 PM | D10: 04:30 | E10: =HOUR(D10)+MINUTE(D10)/100 | F10: =ROUND(INT(E10) + (E10 - INT(E10)) * 100 / 60, 2) | G10: =E10*4 | H10: =LET(total, INT(E10)*60 + (E10-INT(E10))*100, blocks, QUOTIENT(total, 15), extra, MOD(total, 15), units, blocks + IF(extra>=8, 1, 0), units) | I10: 1/1 97153 | J10: =IF(L10="Level 1", VLOOKUP(I10, UserCodes!E:F, 2, FALSE) * H10, IF(L10="Level 2", VLOOKUP(I10, UserCodes!E:F, 2, FALSE) * H10 * 0.8, 0)) | K10: ALI, AMIRA | L10: =VLOOKUP(K10, UserCodes!A:B, 2, FALSE)
A11: Abdulkadir, Nadra | B11: 46004 | C11: 10:00 AM - 01:00 PM | D11: 03:00 | E11: =HOUR(D11)+MINUTE(D11)/100 | F11: =ROUND(INT(E11) + (E11 - INT(E11)) * 100 / 60, 2) | G11: =E11*4 | H11: =LET(total, INT(E11)*60 + (E11-INT(E11))*100, blocks, QUOTIENT(total, 15), extra, MOD(total, 15), units, blocks + IF(extra>=8, 1, 0), units) | I11: O&D 97155 | J11: =IF(L11="Level 1", VLOOKUP(I11, UserCodes!E:F, 2, FALSE) * H11, IF(L11="Level 2", VLOOKUP(I11, UserCodes!E:F, 2, FALSE) * H11 * 0.8, 0)) | K11: Mohamed, Madar | L11: =VLOOKUP(K11, UserCodes!A:B, 2, FALSE)
A12: Abdulkadir, Nadra | B12: 46004 | C12: 09:00 AM - 12:00 PM | D12: 03:00 | E12: =HOUR(D12)+MINUTE(D12)/100 | F12: =ROUND(INT(E12) + (E12 - INT(E12)) * 100 / 60, 2) | G12: =E12*4 | H12: =LET(total, INT(E12)*60 + (E12-INT(E12))*100, blocks, QUOTIENT(total, 15), extra, MOD(total, 15), units, blocks + IF(extra>=8, 1, 0), units) | I12: 1/1 97153 | J12: =IF(L12="Level 1", VLOOKUP(I12, UserCodes!E:F, 2, FALSE) * H12, IF(L12="Level 2", VLOOKUP(I12, UserCodes!E:F, 2, FALSE) * H12 * 0.8, 0)) | K12: ALI, AMIRA | L12: =VLOOKUP(K12, UserCodes!A:B, 2, FALSE)
A13: Abdulkadir, Nadra | B13: 46005 | C13: 09:30 AM - 11:45 AM | D13: 02:15 | E13: =HOUR(D13)+MINUTE(D13)/100 | F13: =ROUND(INT(E13) + (E13 - INT(E13)) * 100 / 60, 2) | G13: =E13*4 | H13: =LET(total, INT(E13)*60 + (E13-INT(E13))*100, blocks, QUOTIENT(total, 15), extra, MOD(total, 15), units, blocks + IF(extra>=8, 1, 0), units) | J13: =IF(L13="Level 1", VLOOKUP(I13, UserCodes!E:F, 2, FALSE) * H13, IF(L13="Level 2", VLOOKUP(I13, UserCodes!E:F, 2, FALSE) * H13 * 0.8, 0)) | K13: Ahmed, Jama | L13: =VLOOKUP(K13, UserCodes!A:B, 2, FALSE) | M13: No schedule
